<?xml version="1.0"?>


<robot xmlns:xacro="https://www.ros.org/wiki/xacro" name="arduinobot">

    <xacro:include filename="$(find arduinobot_description)/urdf/arduinobot_gazebo.xacro"/>
    <xacro:include filename="$(find arduinobot_description)/urdf/arduinobot_ros2_control.xacro"/>

    <xacro:property name="PI" value="3.14159"/>
    <xacro:property name="effort" value="30.0"/>
    <xacro:property name="velocity" value="10.0"/>

    <xacro:macro name="default_inertial" params="mass">
        <inertial>
            <mass value="${mass}"/>
            <inertia    ixx="1.0" ixy="0.0" ixz="0.0"
                        iyy="1.0" iyz="0.0"
                        izz="1.0"/>
        </inertial>
    </xacro:macro>

<xacro:macro name="default_transmission" params="number">
    <transmission name="transmission_${number}">
        <plugin>
            transmission_interface/SimpleTransmission
        </plugin>
        <actuator name="motor_${number}" role="actuator1"/>
        <joint name="joint_${number}" role="joint1">
            <mechanical_reduction>
                1.0
            </mechanical_reduction>
        </joint>
    </transmission>
</xacro:macro>
    
    <link name="world"/> 

    <!-- Base_Simple -->
    <link name="base_link">
        <xacro:default_inertial mass="1.0"/>
        <visual>
            <origin rpy="0 0 0" xyz="0 0 0"/>
            <geometry>
                <mesh filename="package://arduinobot_description/meshes/Base_Simple.stl" scale="0.1 0.1 0.1"/>
            </geometry>
        </visual>
        <collision>
            <origin rpy="0 0 0" xyz="0 0 0"/>
            <geometry>
                <mesh filename="package://arduinobot_description/meshes/Base_Simple.stl" scale="0.1 0.1 0.1"/>
            </geometry>
        </collision>
    </link>

    <!-- Fix-Joint Base_Simple to World -->
    <joint name="virtual_joint" type="fixed">
        <parent link="world"/>
        <child link="base_link"/>
        <origin rpy="0 0 0" xyz="0 0 0"/>
    </joint>

    <!-- Shoulder_Simple -->
    <link name="shoulder_link">
        <xacro:default_inertial mass="0.019"/>
        <visual>
            <origin rpy="${PI/2} 0 0" xyz="0 0 .6"/>
            <geometry>
                <mesh filename="package://arduinobot_description/meshes/Shoulder_Simple.stl" scale="0.1 0.1 0.1"/>
            </geometry>
        </visual>
        <collision>
            <origin rpy="${PI/2} 0 0" xyz="0 0 .6"/>
            <geometry>
                <mesh filename="package://arduinobot_description/meshes/Shoulder_Simple.stl" scale="0.1 0.1 0.1"/>
            </geometry>
        </collision>
    </link>

    <!-- Revolute-Joint Shoulder_Simple to Base_Simple -->
    <joint name="joint_1" type="revolute">
        <parent link="base_link"/>
        <child link="shoulder_link"/>
        <axis xyz="0 1 0"/>
        <origin rpy="0 0 0" xyz="0 0 .75"/>
        <limit lower="-${PI/2}" upper="${PI/2}" effort="${effort}" velocity="${velocity}"/>
    </joint> 

    <!-- Elbow_Simple -->
    <link name="elbow_link">
        <xacro:default_inertial mass="0.019"/>
        <visual>
            <origin rpy="${PI/2} 0 0" xyz="0 0 .6"/>
            <geometry>
                <mesh filename="package://arduinobot_description/meshes/Elbow_Simple.stl" scale="0.1 0.1 0.1"/>
            </geometry>
        </visual>
        <collision>
            <origin rpy="${PI/2} 0 0" xyz="0 0 .6"/>
            <geometry>
                <mesh filename="package://arduinobot_description/meshes/Elbow_Simple.stl" scale="0.1 0.1 0.1"/>
            </geometry>
        </collision>
    </link>

    <!-- Revolute-Joint Elbow_Simple to Shoulder_Simple -->
    <joint name="joint_2" type="revolute">
        <parent link="shoulder_link"/>
        <child link="elbow_link"/>
        <axis xyz="0 1 0"/>
        <origin rpy="0 0 0" xyz="0 0 1.2"/>
        <limit lower="-${PI/2}" upper="${PI/2}" effort="${effort}" velocity="${velocity}"/>
    </joint> 

    <!-- Gripper_Simple -->
    <link name="gripper_link">
        <xacro:default_inertial mass="0.137"/>
        <visual>
            <origin rpy="${PI/2} 0 0" xyz="0 0 .6"/>
            <geometry>
                <mesh filename="package://arduinobot_description/meshes/Gripper_Simple.stl" scale="0.1 0.1 0.1"/>
            </geometry>
        </visual>
        <collision>
            <origin rpy="${PI/2} 0 0" xyz="0 0 .6"/>
            <geometry>
                <mesh filename="package://arduinobot_description/meshes/Gripper_Simple.stl" scale="0.1 0.1 0.1"/>
            </geometry>
        </collision>
    </link>

    <!-- Revolute-Joint Elbow_Simple to Shoulder_Simple -->
    <joint name="joint_3" type="revolute">
        <parent link="elbow_link"/>
        <child link="gripper_link"/>
        <axis xyz="0 1 0"/>
        <origin rpy="0 0 0" xyz="0 0 1.2"/>
        <limit lower="-${PI/2}" upper="${PI/2}" effort="${effort}" velocity="${velocity}"/>
    </joint> 

    <xacro:default_transmission number="1"/>
    <xacro:default_transmission number="2"/>
    <xacro:default_transmission number="3"/>

</robot>